<?xml version="1.0" encoding="UTF-8"?>
<!-- Generated by org.testng.reporters.JUnitReportReporter -->
<testsuite hostname="JishaIbrahim" failures="0" tests="3" name="demo.TestNGRetryFailedDemo" time="0.014" errors="1" timestamp="2024-09-19T19:29:09 IST" skipped="0">
  <testcase classname="demo.TestNGRetryFailedDemo" name="test1" time="0.008"/>
  <testcase classname="demo.TestNGRetryFailedDemo" name="test3" time="0.006">
    <error message="
Cannot instantiate class listeners.RetryAnalyzer" type="org.testng.TestNGException">
      <![CDATA[org.testng.TestNGException: 
Cannot instantiate class listeners.RetryAnalyzer
at org.testng.internal.objects.InstanceCreator.newInstance(InstanceCreator.java:43)
at org.testng.internal.objects.InstanceCreator.newInstance(InstanceCreator.java:61)
at org.testng.ITestObjectFactory.newInstance(ITestObjectFactory.java:10)
at org.testng.internal.objects.SimpleObjectDispenser.dispense(SimpleObjectDispenser.java:61)
at org.testng.internal.objects.GuiceBasedObjectDispenser.dispenseObject(GuiceBasedObjectDispenser.java:41)
at org.testng.internal.objects.GuiceBasedObjectDispenser.dispense(GuiceBasedObjectDispenser.java:31)
at org.testng.internal.BaseTestMethod.computeRetryAnalyzerInstanceToUse(BaseTestMethod.java:868)
at org.testng.internal.BaseTestMethod.getRetryAnalyzerConsideringMethodParameters(BaseTestMethod.java:832)
at org.testng.internal.BaseTestMethod.getRetryAnalyzer(BaseTestMethod.java:693)
at org.testng.internal.invokers.TestInvoker.shouldRetryTestMethod(TestInvoker.java:572)
at org.testng.internal.invokers.TestInvoker.invokeMethod(TestInvoker.java:749)
at org.testng.internal.invokers.TestInvoker.invokeTestMethod(TestInvoker.java:230)
at org.testng.internal.invokers.MethodRunner.runInSequence(MethodRunner.java:63)
at org.testng.internal.invokers.TestInvoker$MethodInvocationAgent.invoke(TestInvoker.java:992)
at org.testng.internal.invokers.TestInvoker.invokeTestMethods(TestInvoker.java:203)
at org.testng.internal.invokers.TestMethodWorker.invokeTestMethods(TestMethodWorker.java:154)
at org.testng.internal.invokers.TestMethodWorker.run(TestMethodWorker.java:134)
at java.base/java.util.ArrayList.forEach(ArrayList.java:1597)
at org.testng.TestRunner.privateRun(TestRunner.java:739)
at org.testng.TestRunner.run(TestRunner.java:614)
at org.testng.SuiteRunner.runTest(SuiteRunner.java:421)
at org.testng.SuiteRunner.runSequentially(SuiteRunner.java:413)
at org.testng.SuiteRunner.privateRun(SuiteRunner.java:373)
at org.testng.SuiteRunner.run(SuiteRunner.java:312)
at org.testng.SuiteRunnerWorker.runSuite(SuiteRunnerWorker.java:52)
at org.testng.SuiteRunnerWorker.run(SuiteRunnerWorker.java:95)
at org.testng.TestNG.runSuitesSequentially(TestNG.java:1274)
at org.testng.TestNG.runSuitesLocally(TestNG.java:1208)
at org.testng.TestNG.runSuites(TestNG.java:1112)
at org.testng.TestNG.run(TestNG.java:1079)
at org.testng.remote.AbstractRemoteTestNG.run(AbstractRemoteTestNG.java:115)
at org.testng.remote.RemoteTestNG.initAndRun(RemoteTestNG.java:293)
at org.testng.remote.RemoteTestNG.main(RemoteTestNG.java:91)
Caused by: java.lang.InstantiationException
at java.base/jdk.internal.reflect.InstantiationExceptionConstructorAccessorImpl.newInstance(InstantiationExceptionConstructorAccessorImpl.java:48)
at java.base/java.lang.reflect.Constructor.newInstanceWithCaller(Constructor.java:502)
at java.base/java.lang.reflect.Constructor.newInstance(Constructor.java:486)
at org.testng.internal.objects.InstanceCreator.newInstance(InstanceCreator.java:40)
... 32 more
]]>
    </error>
  </testcase> <!-- test3 -->
  <testcase classname="demo.TestNGRetryFailedDemo" name="test2" time="0.000"/>
</testsuite> <!-- demo.TestNGRetryFailedDemo -->
